# **程序执行**

本节说明Larva程序的执行流程相关的规则

## **程序启动**

### **初始化**

一个Larva程序启动后首先要做的是各模块的初始化工作，整体流程：
1. 第一步：先将几个标准库的私有模块初始化，由编译器指定顺序，编译器和模块代码实现保证它们能正常初始化
（因为这几个模块并不是单纯的单向依赖关系，比较特殊）
1. 第二步：对主模块执行初始化流程

单个模块的初始化流程是：
1. 第一步：执行所有依赖模块的初始化流程，保证依赖模块都初始化完毕

    *Note*：所以在上面的整体流程中，第二步只要对主模块执行一下流程，程序的所有模块就都初始化完成了，因为主模块是依赖树的根

1. 第二步：对所有全局变量，计算其初始化表达式的值并给它赋值

    单个文件内部的全局变量会按照出现顺序进行初始化，详细的规则和需要注意的见下面的‘需要注意的点’小节

1. 如果模块有初始化函数`__init`，则调用

    初始化函数的签名必须是`void __init()`，如果不是这个，则编译报错

每个模块只会初始化一次，例如主模块导入了模块`x`和`y`，`x`又导入了`y`，则`y`会记录自己是否已被初始化，不会被重复初始化两次

#### **需要注意的点**

初始化有几个需要注意的点

1. Go层面的初始化

    由于Larva是编译为Go执行，最终代码也会遵循Go的初始化原则，如果Native代码包含了Go的全局变量或`init`函数，有几个问题需要注意：
    1. Larva的初始化是程序启动后由booter代码进行的，也就是说Go的各种初始化工作是在Larva程序的初始化和执行之前
    1. Larva层面的代码虽然分了很多模块，但是编译成的Go代码是一个大package，
    因此如果一个程序通过Native代码指定了多个Go层面的全局变量或`init`函数，那么按照Go的规则，
    它们的初始化顺序会按文件名字典序和单个文件中的出现顺序，这个是不可控的，如果没有特殊理由最好不要在Native代码中做这种事，
    如果初始化涉及到Native代码，比较推荐的做法是`__init`做初始化，在其中调用Native代码的函数，这样就保证了模块之间的初始化顺序  
    *Note*：编译成Go的时候不区分package这一点在‘2.2.程序结构’中提到过，在‘5.Native代码开发’中还会详细说明

1. 全局变量的初始化

    请参考‘3.9.全局变量’中初始化一节

### **main函数**

一个Larva程序在编译时需要指定主模块，主模块和其他模块的区别在于：程序启动时以主模块的main函数作为入口

main函数的签名必须是：`public void main()`，程序在做完所有初始化工作后将调用它

## **程序结束**

Larva程序的结束有正常和非正常结束两种，其中正常结束是指：
1. 从main函数中return，程序的退出码为`0`
1. 主fiber出现未捕获的异常而退出，此时会在标准错误输出打印异常信息，程序的退出码为`2`

*Note*：fiber的概念和说明见‘3.6.并发模型’，异常的概念和说明见下面的‘错误处理’一节

非正常退出是指：
1. 接收到操作系统某些信号，并且程序没有捕获处理而导致的退出
1. 在Native代码中直接调用类似`os.Exit`的接口直接退出
1. 运行时引发Go的`panic`而崩溃退出，此时会在标准错误输出额外打印出崩溃时的Larva调用栈
1. 其他原因导致的程序崩溃或结束，例如使用了cgo代码，在C语言层面崩溃了或调用了C的`exit`之类的函数等

如果出现非正常退出，基本都是代码本身有设计或实现的问题，应排查并修复或规避

## **错误处理**

### **异常**

Larva的错误处理一般使用异常（Exception）的方式，异常会从抛出的点回溯当前fiber的调用栈，直到被代码显式捕获，
或者到栈顶被fiber的入口函数默认捕获为止，被捕获的异常会被封装成泛型类`Catched<T>`的对象实例，其中包括原始异常和发生异常时的调用栈信息

异常对象可以使用任何实现了`Throwable`接口的类的对象实例，用内建函数`throw`抛出

例：
```
void f(Callable c)
{
    c.call();
}

public void main()
{
    f([-]{
        throw("exception");
    });
}
```
将以上代码保存在本地开发的模块中，例如在我的测试环境下，模块名为`tmp`，由于main函数中没有捕获抛出的异常，运行后会打印调用栈和异常信息后退出：
```
Traceback (fiber[main]):
  File "/home/xtlisk/larva/tmp/tmp.lar", line 8, in tmp.main
  File "/home/xtlisk/larva/tmp/tmp.lar", line 3, in tmp.f
  File "/home/xtlisk/larva/tmp/tmp.lar", line 9, in closure[tmp:tmp.lar:8:7].call
String: exception
```
输出说明：调用栈的第一行的`Traceback`后面的括号中指明了出现异常的fiber名字，Larva的主fiber默认名字为“main”，
接下来用多个带两空格缩进的行指明了调用栈各层的文件、行号、所在函数或方法名的信息（顺序从栈底到栈顶，即调用者在上面），
其中闭包的函数名中用中括号指明了闭包所在的模块、文件和行、列位置，方便排查问题，最后一行指明了抛出的异常对象的类型和其`str`方法返回的信息

*Note*：当然，如果开发者坚持用返回值的形式来指明错误也是可以的，但Larva的风格是正常代码用异常，
一些比较特殊的地方才用返回值的方式指明或规避错误（例如反射相关接口的使用）

### **异常的捕获**

如上所述，Larva的异常在抛出时会将异常对象和调用栈信息打包为一个`Catch<T>`的对象实例，因此捕获的时候是捕获到这个对象实例，后续统称“异常”，
根据上下文应该能比较容易地判断具体含义

Larva标准库提供了两种捕获异常的方式

#### **使用handle_exc**

在defer中通过内建泛型函数`handle_exc<T>`捕获并处理异常，函数原型说明：

```
public interface ExcHandler<T>
{
    public void handle(Catched<T> catched_exc);
}

public void handle_exc<T>(ExcHandler<T> handler)
```

调用的时候传入一个异常的handler，`handler_exc<T>`的处理规则是：
* 如果没有发生异常，则什么也不做

* 如果发生了异常但不是指定的`T`类型，则继续上抛，也相当放过

    例：
    ```
    public void main()
    {
        defer handle_exc<Throwable>([]{
            public void handle(Catched<Throwable> c)
            {
                println("Throwable");
            }
        });
        defer handle_exc<String>([]{
            public void handle(Catched<String> c)
            {
                println("String");
            }
        });
        defer handle_exc<ValueError>([]{
            public void handle(Catched<ValueError> c)
            {
                println("ValueError");
            }
        });

        throw("exc");
    }

    /*
    输出：
    String
    */
    ```
    这个例子中，由于抛出的是`String`类型的异常，则第一个执行的`handle_exc<ValueError>`将放过它，交由第二个执行的`handle_exc<String>`处理，
    由于已经被处理了，因此第三个执行的`handle_exc<Throwable>`什么也不做

* 如果发生了指定的`T`类型的异常，则捕获住，对其进行处理：
    * 若handler不是nil，则用捕获的异常作为参数调用`handler.handle`方法
    * 若handler是nil，则忽略掉这个异常
    * *Note*：这意味着`handler.handle`方法接收到的参数不会是nil

使用规则：
* `handle_exc`只有在配合`defer`语法的时候才有意义，如果直接调用的话，显然是什么事情都不做的（因为此时流程中没有异常）

    例：
    ```
    public void main()
    {
        defer handle_exc<String>([]{
            public void handle(Catched<String> c)
            {
                println(c);
            }
        });

        println("start");
        println("exc");
        println("end");
    }
    ```

* `handle_exc`只能捕获并处理所在函数或方法栈帧的异常

    例：
    ```
    public void main()
    {
        defer [-]{
            handle_exc<String>(nil);    //这里是处于闭包方法内部，是不能这样捕获main中的异常的
        }.call();

        throw("exc");
    }
    ```

异常的栈帧从属规则：
1. 异常有对函数（或方法）调用栈的栈帧的从属概念
1. 异常抛出时，属于调用`throw`的栈帧
1. 某一栈帧的异常可以在它的`defer handle_exc`调用中捕获
1. 如果异常在当前栈帧没有被捕获，就上抛到上一个栈帧
1. 如果某栈帧已经有异常，又收到下一帧上抛的异常，则上抛的异常覆盖掉原有的异常
1. 异常被捕获后将从当前栈帧清理掉，如果在处理过程中没有上抛到本栈帧的异常，则本栈帧后续`defer handle_exc`将捕获不到异常
1. 可以通过`Catched<T>`的`rethrow()`方法来重新抛出异常

* 注：`rethrow()`是将捕获到的`Catched<T>`的对象实例中的异常和调用栈信息重新打包抛出，就好像没被捕获过一样，
但上抛的是一个新的`Catched<T>`对象实例。需要理解下`rethrow()`和在当前位置`throw(catched_obj.throwed())`的区别，
后者相当于以当前位置的调用栈信息重新包装异常再抛出，调用栈更换为当前位置

#### **使用call_and_catch**

`handle_exc`方式是将捕获的异常交给handler处理，Larva内建库提供了另一种方式，可以使得异常像错误返回一样被处理：
```
//调用输入的Callable对象的call方法，如果出现异常且异常对象类型是T或实现了T接口，则以返回值的形式返回捕获的Catched<T>对象实例
public Catched<T> call_and_catch<T>(Callable callee)
```

例：
```
public void main()
{
    var c = call_and_catch<String>([-]{
        throw("exc");
    });
    if (c !== nil)
    {
        println(c.throwed());   //输出“exc”
    }
}
```

这种形式有点类似其他语言的`try catch`语法，不过只能指定一个需要的异常类型，如果有多个异常类型需要判断，可以先`call_and_catch<Throwable>`，
然后对结果依次做`try_assert_type`，或者嵌套多层

`call_and_catch`的泛型参数的含义和上面`handle_exc`的相同，如果当前异常不符合需要的类型则会重新抛出

### **异常的默认处理方式**

如果异常没有被Larva代码捕获，就会一直上抛到当前fiber的入口处，根据所处不同fiber，有三种处理方式：
1. 对于主fiber，异常将被打印在标准错误输出，然后程序退出，退出码为`2`
1. 如果是一个worker fiber，异常将被发送到`Worker`对象实例的等待通道  
*Note*：worker fiber的内容参考‘3.6.并发模型’和`fiber`模块的说明
1. 其他普通fiber，异常将被打印在标准错误输出，然后fiber结束，程序不受影响
